// === PHASE COMPLETION MARKER - DO NOT MODIFY ===
// Design: Testing
// Phase: 1
// Component: error_handling_tests
// Status: IN_PROGRESS
// Last Modified: 2025-08-24 18:45 UTC
// Next Step: Implement tests for retry with backoff
// =============================================

const { 
  withErrorHandling, 
  retryWithBackoff, 
  generateUserFriendlyErrorMessage,
  CircuitBreaker
} = require('../../functions/error_handling');

describe('Error Handling Functionality', () => {
  describe('withErrorHandling', () => {
    test('should execute function successfully', async () => {
      const testFn = jest.fn().mockResolvedValue('success');
      const wrappedFn = withErrorHandling(testFn);
      
      const result = await wrappedFn('arg1', 'arg2');
      
      expect(testFn).toHaveBeenCalledWith('arg1', 'arg2');
      expect(result).toBe('success');
    });

    test('should handle function errors gracefully', async () => {
      const testFn = jest.fn().mockRejectedValue(new Error('Test error'));
      const wrappedFn = withErrorHandling(testFn);
      
      const result = await wrappedFn('arg1', 'arg2');
      
      expect(testFn).toHaveBeenCalledWith('arg1', 'arg2');
      expect(result).toEqual({
        success: false,
        error: 'An error occurred while processing your request. Please try again.'
      });
    });
  });

  describe('retryWithBackoff', () => {
    beforeEach(() => {
      jest.useFakeTimers();
    });

    afterEach(() => {
      jest.useRealTimers();
    });

    test('should execute function successfully on first try', async () => {
      const testFn = jest.fn().mockResolvedValue('success');
      
      const result = await retryWithBackoff(testFn);
      
      expect(testFn).toHaveBeenCalledTimes(1);
      expect(result).toBe('success');
    });

    test('should retry function on failure and eventually succeed', async () => {
      const testFn = jest.fn()
        .mockRejectedValueOnce(new Error('First failure'))
        .mockRejectedValueOnce(new Error('Second failure'))
        .mockResolvedValue('success');
      
      const result = await retryWithBackoff(testFn, { maxRetries: 3 });
      
      expect(testFn).toHaveBeenCalledTimes(3);
      expect(result).toBe('success');
    });

    test('should throw error after max retries exceeded', async () => {
      const testFn = jest.fn().mockRejectedValue(new Error('Persistent failure'));
      
      await expect(retryWithBackoff(testFn, { maxRetries: 3 })).rejects.toThrow('Persistent failure');
      expect(testFn).toHaveBeenCalledTimes(3);
    });

    test('should implement exponential backoff with jitter', async () => {
      const testFn = jest.fn().mockRejectedValue(new Error('Failure'));
      
      // Start the retry process
      const retryPromise = retryWithBackoff(testFn, { 
        maxRetries: 3, 
        initialDelay: 1000,
        maxDelay: 5000,
        factor: 2
      });
      
      // Advance timers to simulate delays
      await jest.advanceTimersByTimeAsync(1000); // First retry after 1s
      await jest.advanceTimersByTimeAsync(2000); // Second retry after 2s
      await jest.advanceTimersByTimeAsync(4000); // Third retry after 4s
      
      // Wait for the promise to resolve (it will reject after max retries)
      await expect(retryPromise).rejects.toThrow('Failure');
    });
  });

  describe('generateUserFriendlyErrorMessage', () => {
    test('should generate validation error message', () => {
      const message = generateUserFriendlyErrorMessage('VALIDATION_ERROR', {
        tips: 'Check that all fields are filled correctly'
      });
      
      expect(message).toContain('❌ Invalid input');
      expect(message).toContain('Check that all fields are filled correctly');
    });

    test('should generate permission denied message', () => {
      const message = generateUserFriendlyErrorMessage('PERMISSION_DENIED');
      
      expect(message).toContain('❌ Access denied');
      expect(message).toContain('You don\'t have permission to perform this action');
    });

    test('should generate timeout error message', () => {
      const message = generateUserFriendlyErrorMessage('TIMEOUT_ERROR');
      
      expect(message).toContain('❌ Request timeout');
      expect(message).toContain('The request took too long to process');
    });

    test('should generate rate limit exceeded message', () => {
      const message = generateUserFriendlyErrorMessage('RATE_LIMIT_EXCEEDED');
      
      expect(message).toContain('❌ Rate limit exceeded');
      expect(message).toContain('You\'ve made too many requests in a short period');
    });

    test('should generate internal error message', () => {
      const message = generateUserFriendlyErrorMessage('INTERNAL_ERROR');
      
      expect(message).toContain('❌ Internal error');
      expect(message).toContain('Something went wrong on our end');
    });

    test('should generate default error message for unknown error code', () => {
      const message = generateUserFriendlyErrorMessage('UNKNOWN_ERROR');
      
      expect(message).toContain('❌ An error occurred');
      expect(message).toContain('Please try again later');
    });
  });

  describe('CircuitBreaker', () => {
    test('should execute function when circuit is closed', async () => {
      const circuitBreaker = new CircuitBreaker();
      const testFn = jest.fn().mockResolvedValue('success');
      
      const result = await circuitBreaker.execute(testFn);
      
      expect(result).toBe('success');
      expect(testFn).toHaveBeenCalledTimes(1);
      expect(circuitBreaker.getStatus().state).toBe('CLOSED');
    });

    test('should open circuit after failure threshold is reached', async () => {
      const circuitBreaker = new CircuitBreaker({ failureThreshold: 2 });
      const testFn = jest.fn().mockRejectedValue(new Error('Failure'));
      
      // First failure
      await expect(circuitBreaker.execute(testFn)).rejects.toThrow('Failure');
      expect(circuitBreaker.getStatus().state).toBe('CLOSED');
      
      // Second failure - should open circuit
      await expect(circuitBreaker.execute(testFn)).rejects.toThrow('Failure');
      expect(circuitBreaker.getStatus().state).toBe('OPEN');
      
      // Third attempt - should throw circuit breaker error
      await expect(circuitBreaker.execute(testFn)).rejects.toThrow('Circuit breaker is OPEN');
    });

    test('should transition to half-open state after reset timeout', async () => {
      jest.useFakeTimers();
      
      const circuitBreaker = new CircuitBreaker({ 
        failureThreshold: 1, 
        resetTimeout: 5000 
      });
      
      const testFn = jest.fn().mockRejectedValue(new Error('Failure'));
      
      // Cause circuit to open
      await expect(circuitBreaker.execute(testFn)).rejects.toThrow('Failure');
      expect(circuitBreaker.getStatus().state).toBe('OPEN');
      
      // Advance time past reset timeout
      jest.advanceTimersByTime(6000);
      
      // Next execution should transition to HALF_OPEN
      await expect(circuitBreaker.execute(testFn)).rejects.toThrow('Failure');
      // State should be OPEN again because the function failed
      // In a real implementation, it would be HALF_OPEN temporarily
      
      jest.useRealTimers();
    });
  });
});